Workbook

Sheet cashflow
C8: Model Cashflow Spreadsheet for Charter Schools
A11: Cells with red dots in the upper right corner have notes attached--to reveal notes highlight the cell and press the <shift> and <F2> keys simultaneously (Windows95 will reveal notes automatically when cell is highlighted).
A13: Projected Monthly cash flow statement for (name of charter school):
A16: MONTH | B16: Start Up | C16: May | D16: June | E16: July | F16: Aug | G16: Sept | H16: Oct | I16: Nov | J16: Dec | K16: Jan | L16: Feb | M16: Mar | N16: Apr | O16: May | P16: June | Q16: July | R16: August | S16: Total
A17: expected number of students
A18: expected number of exceptional students (do not include gifted students)
A19: Total Number of Children | B19: 0 | C19: =C17+C18 -> 0 | D19: 5 | E19: 5 | F19: 5 | G19: 10 | H19: 16 | I19: 15 | J19: 14 | K19: 15 | L19: 17 | M19: 18 | N19: 16 | O19: 18 | P19: 18 | Q19: 19 | R19: 18 | S19: =S17+S18 -> 0
A21: CASH IN PER MONTH | T21: % of Total Cash In
A23: Tuition | D23: 1800 | E23: 1800 | F23: 1800 | G23: 4000 | H23: 5650 | I23: 3700 | J23: 5000 | K23: ='20242025 Students'!B22 -> 5400 | L23: ='20242025 Students'!C22 -> 6200 | M23: ='20242025 Students'!D22 -> 6200 | N23: ='20242025 Students'!E22 -> 5800 | O23: ='20242025 Students'!F22 -> 6050 | P23: ='20242025 Students'!G22 -> 6600 | Q23: ='20242025 Students'!H22 -> 7000 | R23: ='20242025 Students'!I22 -> 5950 | S23: =SUM(C23:O23) -> 53400 | T23: =S23/$S$33 -> 0.38865477
B24: 3434 | O24: 0 | R24: 4500
A25: Books | G25: 1500 | H25: 1500 | S25: =SUM(C25:O25) -> 3000 | T25: =S25/$S$33 -> 0.021834538
A26: Admission | D26: 1500 | G26: 1500 | H26: 3000 | K26: 1200 | L26: 0 | M26: 600 | P26: 600 | Q26: 0 | R26: 0
A27: Donations | S27: =SUM(C27:O27) -> 0 | T27: =S27/$S$33 -> 0
A28: Directors Contributions: | S28: =SUM(C28:O28) -> 0 | T28: =S28/$S$33 -> 0
A29: Barbara | C29: 2000 | D29: 1000 | E29: 1000 | F29: 1000 | G29: 300 | H29: 3000
A30: Genny | C30: 3700 | D30: 600 | G30: 1000 | H30: 1000
A31: Isaac | C31: 7147 | D31: 5950 | F31: 25000 | G31: 1600 | H31: 5800 | J31: 3600 | Q31: 3500 | R31: 0
A32: Regina | C32: 3000 | D32: 2000 | G32: 1000 | H32: 2500 | J32: 1000 | S32: =SUM(C32:O32) -> 9500 | T32: =S32/$S$33 -> 0.069142703
A33: Total Cash In per month | B33: =SUM(B23:B32) -> 3434 | C33: =SUM(C23:C32) -> 15847 | D33: =SUM(D23:D32) -> 12850 | E33: =SUM(E23:E32) -> 2800 | F33: =SUM(F23:F32) -> 27800 | G33: =SUM(G23:G32) -> 10900 | H33: =SUM(H23:H32) -> 22450 | I33: =SUM(I23:I32) -> 3700 | ... R33: =SUM(R23:R32) -> 10450 | S33: =SUM(C33:O33) -> 137397 | T33: =S33/$S$33 -> 1
A34: MONTH | B34: Start Up | C34: 1- | D34: 2- | E34: 3- | F34: 4- | G34: 5- | H34: 6- | I34: 7- | J34: 8- | K34: 9- | L34: 10- | M34: 11- | O34: 12- | P34: 12- | Q34: 12- | R34: 12- | S34: Total
A36: CASH OUT PER MONTH
S37: =SUM(C37:O37) -> 0 | T37: =S37/$S$33 -> 0
A38: Variable Costs | S38: =SUM(C38:O38) -> 0 | T38: =S38/$S$33 -> 0
A39: Personnel: | S39: =SUM(C39:O39) -> 0 | T39: =S39/$S$33 -> 0
A40: Head Teacher | C40: 1333.3 | D40: 2000 | E40: 2000 | F40: 2000 | G40: 2000 | H40: 2000 | I40: 2000 | J40: 2000 | K40: 1500 | L40: 1500 | M40: 1500 | N40: 1500 | O40: 1500 | P40: 1500 | Q40: 1500 | R40: 1500
A41: Teachers | C41: 533.3 | D41: 800 | E41: 800 | F41: 800 | G41: 800 | H41: 800 | I41: 800 | J41: 800 | K41: 800 | L41: 800 | M41: 800 | N41: 800 | O41: 800 | P41: 800 | Q41: 800 | R41: 800 | S41: =SUM(C41:O41) -> 10133.3 | T41: =S41/$S$33 -> 0.073751974
A42: Teaching Assistants | S42: =SUM(C42:O42) -> 0 | T42: =S42/$S$33 -> 0
A43: Payroll taxes & benefits (var. payroll only) | G43: 229.5 | H43: 460 | I43: 230 | J43: 230 | K43: 230 | L43: 230 | M43: 230 | N43: 230 | O43: 230 | P43: 230 | Q43: 230 | R43: 230 | S43: =SUM(C43:O43) -> 2299.5 | T43: =S43/$S$33 -> 0.016736173
A44: Food | B44: =B33*0.08 -> 274.72 | D44: 562 | E44: 130 | F44: 130 | G44: 200 | I44: 301 | J44: 1299 | O44: 200 | Q44: 30 | R44: 150 | S44: =SUM(C44:O44) -> 2822 | T44: =S44/$S$33 -> 0.020539022
A46: Capital Costs
A47: Fixed asset expenditures
A49: Fixed Costs
A50: Non-Teacher Personnel:
A51: Director's salary | S51: =SUM(C51:O51) -> 0 | T51: =S51/$S$33 -> 0
A52: Other non-teaching salary: | S52: =SUM(C52:O52) -> 0 | T52: =S52/$S$33 -> 0
A53: Security | B53: 400 | C53: 800 | D53: 800 | E53: 800 | F53: 800 | G53: 800 | H53: 800 | I53: 800 | J53: 800 | K53: 800 | L53: 800 | M53: 800 | N53: 800 | O53: 800 | P53: 800 | Q53: 800 | R53: 800
A54: Cleaner | C54: 400 | D54: 600 | E54: 600 | F54: 600 | G54: 600 | H54: 600 | I54: 600 | J54: 600 | K54: 600 | L54: 600 | M54: 600 | N54: 600 | O54: 600 | P54: 600 | Q54: 600 | R54: 600
A55: Payroll taxes & benefits (fixed payroll only) | S55: =SUM(C55:O55) -> 0 | T55: =S55/$S$33 -> 0
A56: Training | S56: =SUM(C56:O56) -> 0 | T56: =S56/$S$33 -> 0
A57: Occupancy:
...

Sheet 20242025 Students
A1: Student Name | B1: Jan | C1: Feb | D1: March | E1: April | F1: May | G1: June | H1: July | I1: August | J1: Total Paid | K1: Balance | L1: Monthly Fee
A2: Tua Atuahene Poku Obrempong | B2: 400 | C2: 400 | D2: 400 | E2: 400 | F2: 400 | G2: 400 | H2: 400 | I2: 400 | J2: =SUM(B2:I2) -> 3200 | K2: =(L2*COUNTIF(B2:I2,"<>A"))-SUM(B2:I2) -> 0 | L2: 400
A3: Jantuah Asare Michael | B3: 400 | C3: 400 | D3: 400 | E3: 400 | F3: 400 | G3: 400 | H3: 400 | I3: 400 | J3: =SUM(B3:I3) -> 3200 | K3: =(L3*COUNTIF(B3:I3,"<>A"))-SUM(B3:I3) -> 0 | L3: 400
A4: Nana Akosua Nti Afriyie | B4: 400 | C4: 400 | D4: 400 | E4: 400 | F4: 400 | G4: 400 | H4: 400 | I4: A | J4: =SUM(B4:I4) -> 2800 | K4: =(L4*COUNTIF(B4:I4,"<>A"))-SUM(B4:I4) -> 0 | L4: 400
A5: Ackah Esi Zoya | B5: 400 | C5: 400 | D5: 400 | E5: 400 | F5: 400 | G5: 400 | H5: 400 | I5: 400 | J5: =SUM(B5:I5) -> 3200 | K5: =(L5*COUNTIF(B5:I5,"<>A"))-SUM(B5:I5) -> 0 | L5: 400
A6: Katakyie Adubofuor Barima | B6: 400 | C6: 400 | D6: 400 | E6: 400 | F6: 400 | G6: 400 | H6: 400 | I6: 400 | J6: =SUM(B6:I6) -> 3200 | K6: =(L6*COUNTIF(B6:I6,"<>A"))-SUM(B6:I6) -> 0 | L6: 400
A7: Agyemang Ohemaa Gyamfua | H7: 400 | I7: 400 | J7: =SUM(H7:I7) -> 800 | K7: =(L7*COUNTIF(H7:I7,"<>A"))-SUM(H7:I7) -> 0 | L7: 400
A8: Kendra Nana Yaa Konadu | G8: 400 | H8: 400 | I8: 400 | J8: =SUM(G8:I8) -> 1200 | K8: =(L8*COUNTIF(G8:I8,"<>A"))-SUM(G8:I8) -> 0 | L8: 400
A9: Attah Mensah Nana Boateng | B9: 400 | C9: 400 | D9: 400 | E9: 400 | F9: 400 | G9: 400 | H9: 400 | I9: 400 | J9: =SUM(B9:I9) -> 3200 | K9: =(L9*COUNTIF(B9:I9,"<>A"))-SUM(B9:I9) -> 0 | L9: 400
A10: Arthur Forson Jayla | B10: 400 | C10: 400 | D10: 400 | E10: 400 | F10: 400 | G10: 400 | H10: 400 | I10: 400 | J10: =SUM(B10:I10) -> 3200 | K10: =(L10*COUNTIF(B10:I10,"<>A"))-SUM(B10:I10) -> 0 | L10: 400
A11: Nyametease Annin Yeboah | B11: 300 | C11: 300 | D11: 300 | E11: 300 | F11: 300 | G11: 300 | H11: 300 | I11: 300 | J11: =SUM(B11:I11) -> 2400 | K11: =(L11*COUNTIF(B11:I11,"<>A"))-SUM(B11:I11) -> 0 | L11: 300
A12: Nyamedome Annin Yeboah | B12: 300 | C12: 300 | D12: 300 | E12: 300 | F12: 300 | G12: 300 | H12: 300 | I12: 300 | J12: =SUM(B12:I12) -> 2400 | K12: =(L12*COUNTIF(B12:I12,"<>A"))-SUM(B12:I12) -> 0 | L12: 300
A13: Devine Ryker | B13: 400 | C13: 400 | D13: 400 | E13: 400 | F13: 400 | G13: 400 | H13: 400 | I13: 400 | J13: =SUM(B13:I13) -> 3200 | K13: =(L13*COUNTIF(B13:I13,"<>A"))-SUM(B13:I13) -> 0 | L13: 400
A14: Frimpong Abena Serwaa | B14: 400 | C14: 400 | D14: 400 | E14: 400 | F14: 400 | G14: 400 | H14: 400 | I14: 350 | J14: =SUM(B14:I14) -> 3150 | K14: =(L14*COUNTIF(B14:I14,"<>A"))-SUM(B14:I14) -> 50 | L14: 400
A15: Boakye Agyemang Spencer Nana Eshun | B15: 400 | C15: 400 | D15: 400 | E15: 400 | F15: 400 | G15: 400 | H15: 400 | I15: 400 | J15: =SUM(B15:I15) -> 3200 | K15: =(L15*COUNTIF(B15:I15,"<>A"))-SUM(B15:I15) -> 0 | L15: 400
A16: Ayama Elizabeth | B16: 400 | C16: 400 | D16: 400 | E16: 400 | F16: 250 | G16: 0 | H16: 0 | I16: A | J16: =SUM(B16:I16) -> 1850 | K16: =(L16*COUNTIF(B16:I16,"<>A"))-SUM(B16:I16) -> 950 | L16: 400
A17: Antwi Bosiako Raphael | B17: 400 | C17: 400 | D17: 400 | E17: 400 | F17: 400 | G17: 400 | H17: 400 | I17: 400 | J17: =SUM(B17:I17) -> 3200 | K17: =(L17*COUNTIF(B17:I17,"<>A"))-SUM(B17:I17) -> 0 | L17: 400
A18: Apenten Kofi Elisha | B18: A | C18: 400 | D18: 400 | E18: 400 | F18: 400 | G18: 400 | H18: 400 | I18: 400 | J18: =SUM(B18:I18) -> 2800 | K18: =(L18*COUNTIF(B18:I18,"<>A"))-SUM(B18:I18) -> 0 | L18: 400
A19: Anim Yeboah Beatrice | B19: A | C19: 400 | D19: 400 | E19: A | F19: A | G19: 400 | H19: 400 | I19: 200 | J19: =SUM(B19:I19) -> 1800 | K19: 0 | L19: 400
A20: Oppong Fosu Eric | B20: A | C20: A | D20: A | E20: A | F20: 400 | G20: 400 | H20: 400 | I20: A | J20: =SUM(B20:I20) -> 1200 | K20: =(L20*COUNTIF(B20:I20,"<>A"))-SUM(B20:I20) -> 0 | L20: 400
A22: Total Tuition Per Month | B22: =SUM(B2:B20) -> 5400 | C22: =SUM(C2:C20) -> 6200 | D22: =SUM(D2:D20) -> 6200 | E22: =SUM(E2:E20) -> 5800 | F22: =SUM(F2:F20) -> 6050 | G22: =SUM(G2:G20) -> 6600 | H22: =SUM(H2:H20) -> 7000 | I22: =SUM(I2:I20) -> 5950 | ... L22: =SUM(L2:L20) -> 7400
A23: Number on Roll | B23: =COUNT(B2:B20) -> 14 | C23: =COUNT(C2:C20) -> 16 | D23: =COUNT(D2:D20) -> 16 | E23: =COUNT(E2:E20) -> 15 | F23: =COUNT(F2:F20) -> 16 | G23: =COUNT(G2:G20) -> 18 | H23: =COUNT(H2:H20) -> 19 | I23: 19

Sheet 20252026 students
A1: Student Name | B1: September | C1: Oct | D1: Nov | E1: Dec | F1: Jan | G1: Feb | H1: March | I1: April | J1: May | K1: June | L1: July | M1: Total Paid | N1: Balance | O1: Monthly Fee
A2: Tua Atuahene Poku Obrempong | B2: 400 | C2: 400 | D2: 0 | E2: 400 | F2: 400 | G2: 400 | H2: A | I2: A | J2: A | K2: A | L2: A | M2: =SUM(B2:L2) -> 2000 | N2: =(O2*COUNTIF(B2:L2,"<>A"))-SUM(B2:L2) -> 400 | O2: 400
A3: Jantuah Asare Michael | B3: 400 | C3: 400 | D3: 400 | E3: 400 | F3: 400 | G3: 400 | H3: A | I3: A | J3: A | K3: A | L3: A | M3: =SUM(B3:L3) -> 2400 | N3: =(O3*COUNTIF(B3:L3,"<>A"))-SUM(B3:L3) -> 0 | O3: 400
A4: Ackah Esi Zoya | B4: 400 | C4: 400 | D4: 400 | E4: 400 | F4: 400 | G4: 400 | H4: A | I4: A | J4: A | K4: A | L4: A | M4: =(N4*COUNTIF(B4:K4,"<>A"))-SUM(B4:K4) -> -2400 | N4: =(O4*COUNTIF(B4:L4,"<>A"))-SUM(B4:L4) -> 0 | O4: 400
A5: Katakyie Adubofuor Barima | B5: 400 | C5: 400 | D5: 400 | E5: 400 | F5: 400 | G5: 400 | H5: A | I5: A | J5: A | K5: A | L5: A | M5: =SUM(B5:L5) -> 2400 | N5: =(O5*COUNTIF(B5:L5,"<>A"))-SUM(B5:L5) -> 0 | O5: 400
A6: Agyemang Ohemaa Gyamfua | B6: 400 | C6: 400 | D6: 400 | E6: 400 | F6: 400 | G6: 400 | H6: A | I6: A | J6: A | K6: A | L6: A | M6: =SUM(B6:L6) -> 2400 | N6: =(O6*COUNTIF(B6:L6,"<>A"))-SUM(B6:L6) -> 0 | O6: 400
A7: Attah Mensah Nana Boateng | B7: 400 | C7: 400 | D7: 400 | E7: 0 | F7: 400 | G7: 400 | H7: A | I7: A | J7: A | K7: A | L7: A | M7: =SUM(B7:L7) -> 2000 | N7: =(O7*COUNTIF(B7:L7,"<>A"))-SUM(B7:L7) -> 400 | O7: 400
A8: Arthur Forson Jayla | B8: 400 | C8: 400 | D8: 400 | E8: 400 | F8: 400 | G8: 400 | H8: A | I8: A | J8: A | K8: A | L8: A | M8: =SUM(B8:L8) -> 2400 | N8: =(O8*COUNTIF(B8:L8,"<>A"))-SUM(B8:L8) -> 0 | O8: 400
A9: Nyametease Annin Yeboah | B9: 300 | C9: 300 | D9: 300 | E9: 300 | F9: 300 | G9: 300 | H9: A | I9: A | J9: A | K9: A | L9: A | M9: =SUM(B9:L9) -> 1800 | N9: =(O9*COUNTIF(B9:L9,"<>A"))-SUM(B9:L9) -> 0 | O9: 300
A10: Nyamedome Annin Yeboah | B10: 300 | C10: 300 | D10: 300 | E10: 300 | F10: 300 | G10: 300 | H10: A | I10: A | J10: A | K10: A | L10: A | M10: =SUM(B10:L10) -> 1800 | N10: =(O10*COUNTIF(B10:L10,"<>A"))-SUM(B10:L10) -> 0 | O10: 300
A11: Devine Ryker | B11: 400 | C11: 400 | D11: 400 | E11: 400 | F11: 400 | G11: 400 | H11: A | I11: A | J11: A | K11: A | L11: A | M11: =SUM(B11:L11) -> 2400 | N11: =(O11*COUNTIF(B11:L11,"<>A"))-SUM(B11:L11) -> 0 | O11: 400
A12: Frimpong Abena Serwaa | B12: 400 | C12: 100 | D12: 0 | E12: 0 | F12: 0 | G12: 0 | H12: A | I12: A | J12: A | K12: A | L12: A | M12: =SUM(B12:L12) -> 500 | N12: =(O12*COUNTIF(B12:L12,"<>A"))-SUM(B12:L12) -> 1900 | O12: 400
A13: Boakye Agyemang Spencer Nana Eshun | B13: 400 | C13: 400 | D13: 400 | E13: 400 | F13: 400 | G13: 400 | H13: A | I13: A | J13: A | K13: A | L13: A | M13: =SUM(B13:L13) -> 2400 | N13: =(O13*COUNTIF(B13:L13,"<>A"))-SUM(B13:L13) -> 0 | O13: 400
A14: Ayama Elizabeth | B14: A | C14: A | D14: 200 | E14: 0 | F14: 0 | G14: 0 | H14: A | I14: A | J14: A | K14: A | L14: A | M14: =SUM(B14:L14) -> 200 | N14: =(O14*COUNTIF(B14:L14,"<>A"))-SUM(B14:L14) -> 1400 | O14: 400
A15: Antwi Bosiako Raphael | B15: 400 | C15: 400 | D15: 400 | E15: 400 | F15: 400 | G15: 400 | H15: A | I15: A | J15: A | K15: A | L15: A | M15: =SUM(B15:L15) -> 2400 | N15: =(O15*COUNTIF(B15:L15,"<>A"))-SUM(B15:L15) -> 0 | O15: 400
A16: Apenten Kofi Elisha | B16: 400 | C16: 400 | D16: 400 | E16: 400 | F16: 400 | G16: 400 | H16: A | I16: A | J16: A | K16: A | L16: A | M16: =SUM(B16:L16) -> 2400 | N16: =(O16*COUNTIF(B16:L16,"<>A"))-SUM(B16:L16) -> 0 | O16: 400
A17: Anim Yeboah Beatrice | B17: 400 | C17: 400 | D17: 400 | E17: 0 | F17: 0 | G17: A | H17: A | I17: A | J17: A | K17: A | L17: A | M17: =SUM(B17:L17) -> 1200 | N17: =(O17*COUNTIF(B17:L17,"<>A"))-SUM(B17:L17) -> 800 | O17: 400
A18: Oppong Fosu Eric | B18: A | C18: A | D18: 350 | E18: 0 | F18: 0 | G18: 0 | H18: A | I18: A | J18: A | K18: A | L18: A | M18: =SUM(B18:L18) -> 350 | N18: =(O18*COUNTIF(B18:L18,"<>A"))-SUM(B18:L18) -> 1250 | O18: 400
A19: Benjamin Kweku | C19: 400 | D19: 400 | E19: 400 | F19: 400 | G19: 400 | H19: A | I19: A | J19: A | K19: A | L19: A | M19: =SUM(B19:L19) -> 2000 | N19: =(O19*COUNTIF(C19:L19,"<>A"))-SUM(C19:L19) -> 0 | O19: 400
A20: Samuel Asare | C20: 400 | D20: 400 | E20: 400 | F20: 400 | G20: 400 | H20: A | I20: A | J20: A | K20: A | L20: A | M20: =SUM(B20:L20) -> 2000 | N20: =(O20*COUNTIF(C20:L20,"<>A"))-SUM(C20:L20) -> 0 | O20: 400
A21: Sharif Mujaheed | C21: 400 | D21: 400 | E21: 400 | F21: 400 | G21: 400 | H21: A | I21: A | J21: A | K21: A | L21: A | M21: =SUM(B21:L21) -> 2000 | N21: =(O21*COUNTIF(C21:L21,"<>A"))-SUM(C21:L21) -> 0 | O21: 400
A22: Lilibeth | D22: 400 | E22: 400 | F22: 400 | G22: 400 | H22: A | I22: A | J22: A | K22: A | L22: A | M22: =SUM(D22:L22) -> 1600 | N22: =(O22*COUNTIF(D22:L22,"<>A"))-SUM(D22:L22) -> 0 | O22: 400
A23: Annin Yeboah | D23: 300 | E23: 300 | F23: 300 | G23: 300 | H23: A | I23: A | J23: A | K23: A | L23: A | M23: =SUM(D23:L23) -> 1200 | N23: =(O23*COUNTIF(D23:L23,"<>A"))-SUM(D23:L23) -> 0 | O23: 300
A24: Mark Marshall | G24: 0
A25: Jayden kekeli Kpodo | G25: 400
A26: Kiara manu | G26: 400
A27: Carysel Kwarteng | F27: 400 | G27: 400
A28: Ciara | G28: 0
A29: Boatemaa | G29: 400
A30: Liana | F30: 400 | G30: 400
A31: Total Tuition Per Month | B31: =SUM(B2:B30) -> 5800 | C31: =SUM(C2:C30) -> 6700 | D31: =SUM(D2:D30) -> 7450 | E31: =SUM(E2:E30) -> 6500 | F31: =SUM(F2:F30) -> 7700 | G31: =SUM(G2:G30) -> 8900 | H31: =SUM(H2:H30) -> 0 | I31: =SUM(I2:I30) -> 0 | ... O31: =SUM(O2:O30) -> 8500
A32: Number on Roll | B32: =COUNT(B2:B21) -> 15 | C32: =COUNT(C2:C21) -> 18 | D32: =COUNT(D2:D28) -> 22 | E32: =COUNT(E2:E28) -> 22 | F32: =COUNT(F2:F28) -> 23 | G32: =COUNT(G2:G30) -> 28 | H32: =COUNT(H2:H28) -> 0 | I32: =COUNT(I2:I28) -> 0 | J32: =COUNT(J2:J28) -> 0 | K32: =COUNT(K2:K28) -> 0 | L32: =COUNT(L2:L28) -> 0

Sheet cashflow 20252026 
C8: Model Cashflow Spreadsheet for Charter Schools
A11: Cells with red dots in the upper right corner have notes attached--to reveal notes highlight the cell and press the <shift> and <F2> keys simultaneously (Windows95 will reveal notes automatically when cell is highlighted).
A13: Projected Monthly cash flow statement for (name of charter school):
A16: MONTH | B16: Start Up | C16: September | D16: October | E16: November | F16: December | G16: January | H16: February | I16: March | J16: April | K16: May | L16: June | M16: July | N16: August | O16: September | P16: Total
A17: expected number of students
A18: expected number of exceptional students (do not include gifted students)
A19: Total Number of Children | B19: 0 | C19: 17 | D19: 21 | E19: ='20252026 students'!D32 -> 22 | F19: ='20252026 students'!E32 -> 22 | G19: ='20252026 students'!F32 -> 23 | H19: ='20252026 students'!G32 -> 28 | I19: ='20252026 students'!H32 -> 0 | J19: ='20252026 students'!I32 -> 0 | K19: ='20252026 students'!J32 -> 0 | L19: ='20252026 students'!K32 -> 0 | ... O19: ='20252026 students'!N32 | P19: =P17+P18 -> 0
A21: CASH IN PER MONTH | Q21: % of Total Cash In
A23: Tuition | C23: ='20252026 students'!B31 -> 5800 | D23: ='20252026 students'!C31 -> 6700 | E23: ='20252026 students'!D31 -> 7450 | F23: ='20252026 students'!E31 -> 6500 | G23: ='20252026 students'!F31 -> 7700 | H23: ='20252026 students'!G31 -> 8900 | I23: =#REF! -> #REF! | J23: =#REF! -> #REF! | K23: =#REF! -> #REF! | L23: =#REF! -> #REF! | M23: =#REF! -> #REF! | N23: =#REF! -> #REF! | O23: =#REF! -> #REF! | P23: =SUM(C23:N23) -> #REF! | Q23: =P23/$P$33 -> #REF!
B24: 0
A25: Books | C25: 700 | H25: 550 | P25: =SUM(C25:N25) -> 1250 | Q25: =P25/$P$33 -> #REF!
A26: Admission | C26: 0 | D26: 1200 | E26: 400 | F26: 0 | G26: 800 | H26: 1600 | I26: 0 | J26: 0 | K26: 0 | L26: 0 | M26: 0 | N26: 0 | O26: 0
A27: Donations | P27: =SUM(C27:N27) -> 0 | Q27: =P27/$P$33 -> #REF!
A28: Directors Contributions: | P28: =SUM(C28:N28) -> 0 | Q28: =P28/$P$33 -> #REF!
A29: Barbara
A30: Genny
A31: Isaac | C31: 0 | D31: 0 | E31: 0 | F31: 0 | G31: 0 | H31: 0 | I31: 0 | J31: 0 | K31: 0 | L31: 0 | M31: 0 | N31: 0 | O31: 0
A32: Regina | P32: =SUM(C32:N32) -> 0 | Q32: =P32/$P$33 -> #REF!
A33: Total Cash In per month | B33: 854 | C33: =SUM(C23:C32) -> 6500 | D33: =SUM(D23:D32) -> 7900 | E33: =SUM(E23:E32) -> 7850 | F33: =SUM(F23:F32) -> 6500 | G33: =SUM(G23:G32) -> 8500 | H33: =SUM(H23:H32) -> 11050 | I33: =SUM(I23:I32) -> #REF! | J33: =SUM(J23:J32) -> #REF! | ... O33: =SUM(O23:O32) -> #REF! | P33: =SUM(C33:N33) -> #REF! | Q33: =P33/$P$33 -> #REF!
A34: MONTH | B34: Start Up | C34: 12- | D34: 12- | E34: 12- | F34: 12- | G34: 12- | H34: 12- | I34: 12- | J34: 12- | K34: 12- | L34: 12- | M34: 12- | N34: 12- | O34: 12- | P34: Total
A36: CASH OUT PER MONTH
P37: =SUM(C37:N37) -> 0 | Q37: =P37/$P$33 -> #REF!
A38: Variable Costs | P38: =SUM(C38:N38) -> 0 | Q38: =P38/$P$33 -> #REF!
A39: Personnel: | P39: =SUM(C39:N39) -> 0 | Q39: =P39/$P$33 -> #REF!
A40: Head Teacher | C40: 1500 | D40: 1500 | E40: 1500 | F40: 1500 | G40: 1500 | H40: 1500 | I40: 0 | J40: 0 | K40: 0 | L40: 0 | M40: 0 | N40: 0 | O40: 0
A41: Teachers | C41: 800 | D41: 800 | E41: 800 | F41: 800 | G41: 800 | H41: 800 | I41: 0 | J41: 0 | K41: 0 | L41: 0 | M41: 800 | N41: 800 | O41: 800 | P41: =SUM(C41:N41) -> 6400 | Q41: =P41/$P$33 -> #REF!
A42: Teaching Assistants | P42: =SUM(C42:N42) -> 0 | Q42: =P42/$P$33 -> #REF!
A43: Payroll taxes & benefits (var. payroll only) | C43: 0 | E43: 0 | G43: 400 | H43: 400 | I43: 0 | J43: 0 | K43: 0 | L43: 0 | M43: 0 | N43: 0 | O43: 0 | P43: =SUM(C43:N43) -> 800 | Q43: =P43/$P$33 -> #REF!
A44: Food | B44: 0 | C44: 0 | D44: 0 | E44: 0 | F44: 0 | G44: 220 | H44: 40 | I44: 0 | J44: 0 | K44: 0 | L44: 0 | M44: 0 | N44: 0 | O44: 0 | P44: =SUM(C44:N44) -> 260 | Q44: =P44/$P$33 -> #REF!
A46: Capital Costs
A47: Fixed asset expenditures
A49: Fixed Costs
A50: Non-Teacher Personnel:
A51: Director's salary | P51: =SUM(C51:N51) -> 0 | Q51: =P51/$P$33 -> #REF!
A52: Other non-teaching salary: | P52: =SUM(C52:N52) -> 0 | Q52: =P52/$P$33 -> #REF!
A53: Security | C53: 800 | D53: 800 | E53: 800 | F53: 800 | G53: 800 | H53: 800 | I53: 0 | J53: 0 | K53: 0 | L53: 0 | M53: 0 | N53: 0 | O53: 800
A54: Cleaner | C54: 600 | D54: 600 | E54: 600 | F54: 600 | G54: 600 | H54: 600 | I54: 0 | J54: 0 | K54: 0 | L54: 0 | M54: 0 | N54: 0 | O54: 600
A55: Payroll taxes & benefits (fixed payroll only) | C55: 230 | D55: 230 | E55: 230 | F55: 230 | G55: 230 | H55: 230 | P55: =SUM(C55:N55) -> 1380 | Q55: =P55/$P$33 -> #REF!
A56: Training | P56: =SUM(C56:N56) -> 0 | Q56: =P56/$P$33 -> #REF!
A57: Occupancy:
...

Sheet Tasks
A1: Task | B1: Priority | C1: Status | D1: Start date | E1: End date | F1: Notes
A2: Health drive | B2: P3 | C2: Not started
A3: Social Media Attraction | B3: P3 | C3: Not started
A4: Door to Door | B4: P3 | C4: Not started
A5: Meet your ward and faciltator day | B5: P3 | C5: Not started
A6: Funfair | B6: P1
A7: Affiliation with a bigger school | B7: P3
